<mujoco model="unnamed_model">
  <compiler autolimits="true" angle="radian"/>
  <visual>
    <global azimuth="160" elevation="-20"/>
    <headlight ambient="0.29999999999999999 0.29999999999999999 0.29999999999999999" diffuse="0.59999999999999998 0.59999999999999998 0.59999999999999998" specular="0 0 0"/>
    <rgba haze="0.14999999999999999 0.25 0.34999999999999998 1"/>
  </visual>
  <default>
    <default class="/"/>
    <default class="scene/">
      <default class="scene/so101_new_calib">
        <joint armature="0.0050000000000000001" damping="1" frictionloss="0.10000000000000001"/>
        <position kp="50"/>
        <default class="scene/visual">
          <geom type="mesh" contype="0" conaffinity="0" group="2"/>
        </default>
        <default class="scene/collision">
          <geom group="3"/>
        </default>
      </default>
      <default class="scene/sts3215">
        <joint armature="0.028000000000000001" damping="0.59999999999999998" frictionloss="0.051999999999999998"/>
        <geom contype="0" conaffinity="0"/>
        <position kp="17.800000000000001"/>
      </default>
      <default class="scene/backlash">
        <joint limited="true" range="-0.0087266462599716477 0.0087266462599716477" armature="0.01" damping="0.01" frictionloss="0"/>
      </default>
    </default>
  </default>
  <asset>
    <texture name="scene//unnamed_texture_0" type="skybox" builtin="gradient" rgb1="0.29999999999999999 0.5 0.69999999999999996" rgb2="0 0 0" width="512" height="3072"/>
    <texture name="scene/groundplane" type="2d" builtin="checker" rgb1="0.20000000000000001 0.29999999999999999 0.40000000000000002" rgb2="0.10000000000000001 0.20000000000000001 0.29999999999999999" mark="edge" markrgb="0.80000000000000004 0.80000000000000004 0.80000000000000004" width="300" height="300"/>
    <material name="scene/groundplane" class="scene/" texture="scene/groundplane" texrepeat="5 5" texuniform="true" reflectance="0.20000000000000001"/>
    <mesh name="scene/waveshare_mounting_plate_so101_v2" class="scene/" file="waveshare_mounting_plate_so101_v2-bdc4594c1957f44d73e6a5364f7b03bd093c6890.stl"/>
    <mesh name="scene/sts3215_03a_v1" class="scene/" file="sts3215_03a_v1-48096645b134fc6e7596205abc199b6bd4d42d2e.stl"/>
    <mesh name="scene/motor_holder_so101_base_v1" class="scene/" file="motor_holder_so101_base_v1-ba6f82816114ac2a03d9c52c36542b5b83e1cacb.stl"/>
    <mesh name="scene/wrist_roll_follower_so101_v1" class="scene/" file="wrist_roll_follower_so101_v1-1390ac1f92d1a9a8eca02928a45b1490c8f378b2.stl"/>
    <mesh name="scene/moving_jaw_so101_v1" class="scene/" file="moving_jaw_so101_v1-b6a41be828f9c5577dd0199b7e4c8d35c927ded2.stl"/>
    <mesh name="scene/base_motor_holder_so101_v1" class="scene/" file="base_motor_holder_so101_v1-bc95b2736c48967dd6bd8e8a2f52242bc89646fa.stl"/>
    <mesh name="scene/upper_arm_so101_v1" class="scene/" file="upper_arm_so101_v1-b939afe42bcca9c3e448797ee275d5166c6b3dcb.stl"/>
    <mesh name="scene/wrist_roll_pitch_so101_v2" class="scene/" file="wrist_roll_pitch_so101_v2-cbb1b45ea25e6399a1d3321c70d7fcaf37441e6d.stl"/>
    <mesh name="scene/under_arm_so101_v1" class="scene/" file="under_arm_so101_v1-f9b17147dd5786ea6c729dd8439bc8e43512d671.stl"/>
    <mesh name="scene/rotation_pitch_so101_v1" class="scene/" file="rotation_pitch_so101_v1-ec1d01337ede85fa8589cca645336a7a18af2870.stl"/>
    <mesh name="scene/motor_holder_so101_wrist_v1" class="scene/" file="motor_holder_so101_wrist_v1-4b80e458bdc13da15d80c2f1aac2568a487039c8.stl"/>
    <mesh name="scene/sts3215_03a_no_horn_v1" class="scene/" file="sts3215_03a_no_horn_v1-e9103d14a7c0f059d5c33db4828d79632d0a28a3.stl"/>
    <mesh name="scene/base_so101_v2" class="scene/" file="base_so101_v2-6749fa4eebf909cd3026a16775220eaefca3c50f.stl"/>
    <material name="scene/base_motor_holder_so101_v1_material" class="scene/" rgba="1 0.81999999999999995 0.12 1"/>
    <material name="scene/base_so101_v2_material" class="scene/" rgba="1 0.81999999999999995 0.12 1"/>
    <material name="scene/sts3215_03a_v1_material" class="scene/" rgba="0.10000000000000001 0.10000000000000001 0.10000000000000001 1"/>
    <material name="scene/waveshare_mounting_plate_so101_v2_material" class="scene/" rgba="1 0.81999999999999995 0.12 1"/>
    <material name="scene/motor_holder_so101_base_v1_material" class="scene/" rgba="1 0.81999999999999995 0.12 1"/>
    <material name="scene/rotation_pitch_so101_v1_material" class="scene/" rgba="1 0.81999999999999995 0.12 1"/>
    <material name="scene/upper_arm_so101_v1_material" class="scene/" rgba="1 0.81999999999999995 0.12 1"/>
    <material name="scene/under_arm_so101_v1_material" class="scene/" rgba="1 0.81999999999999995 0.12 1"/>
    <material name="scene/motor_holder_so101_wrist_v1_material" class="scene/" rgba="1 0.81999999999999995 0.12 1"/>
    <material name="scene/sts3215_03a_no_horn_v1_material" class="scene/" rgba="0.10000000000000001 0.10000000000000001 0.10000000000000001 1"/>
    <material name="scene/wrist_roll_pitch_so101_v2_material" class="scene/" rgba="1 0.81999999999999995 0.12 1"/>
    <material name="scene/wrist_roll_follower_so101_v1_material" class="scene/" rgba="1 0.81999999999999995 0.12 1"/>
    <material name="scene/moving_jaw_so101_v1_material" class="scene/" rgba="1 0.81999999999999995 0.12 1"/>
  </asset>
  <worldbody>
    <geom name="//unnamed_geom_0" class="/" type="plane" size="2 2 0.10000000000000001" rgba="0.80000000000000004 0.90000000000000002 0.80000000000000004 1"/>
    <body name="scene/">
      <light name="scene//unnamed_light_0" class="scene/" directional="true" pos="0 0 3.5" dir="0 0 -1"/>
      <geom name="scene/floor" class="scene/" type="plane" size="0 0 0.050000000000000003" material="scene/groundplane" pos="0 0 0"/>
      <body name="scene/base" childclass="scene/so101_new_calib" pos="0 0 0" quat="1 0 0 0">
        <inertial pos="0.0137179 -5.1971100000000001e-05 0.033484300000000002" mass="0.14699999999999999" fullinertia="0.00011468600000000001 0.000136117 0.000130364 -4.5978699999999999e-07 4.9715099999999996e-06 9.7527499999999998e-08"/>
        <geom name="scene//unnamed_geom_1" class="scene/visual" type="mesh" material="scene/base_motor_holder_so101_v1_material" pos="-0.00636471 -9.94414e-05 -0.0023999999999999998" quat="0.5 0.5 0.5 0.5" mesh="scene/base_motor_holder_so101_v1"/>
        <geom name="scene//unnamed_geom_2" class="scene/visual" type="mesh" material="scene/base_so101_v2_material" pos="-0.00636471 -8.9765700000000002e-09 -0.0023999999999999998" quat="0.5 0.5 0.5 0.5" mesh="scene/base_so101_v2"/>
        <geom name="scene//unnamed_geom_3" class="scene/visual" type="mesh" material="scene/sts3215_03a_v1_material" pos="0.026335299999999999 -8.9765700000000002e-09 0.043700000000000003" quat="1 -2.85511e-16 -9.6443300000000005e-17 6.12908e-16" mesh="scene/sts3215_03a_v1"/>
        <geom name="scene//unnamed_geom_4" class="scene/visual" type="mesh" material="scene/waveshare_mounting_plate_so101_v2_material" pos="-0.030982699999999998 -0.00019944099999999999 0.047399999999999998" quat="0.5 0.5 0.5 0.5" mesh="scene/waveshare_mounting_plate_so101_v2"/>
        <site name="scene/baseframe" group="3" pos="8.6736199999999997e-19 9.5559600000000001e-18 3.4694499999999997e-18" quat="1 -8.1739600000000001e-19 3.7839199999999998e-17 2.2204499999999999e-16"/>
        <body name="scene/shoulder" pos="0.038835300000000003 -8.9765700000000002e-09 0.062399999999999997" quat="3.5616699999999998e-16 1.22818e-15 -1 -4.1463499999999998e-16">
          <joint name="scene/shoulder_pan" class="scene/sts3215" type="hinge" axis="0 0 1" range="-1.9198621771937616 1.9198621771937634"/>
          <inertial pos="-0.0307604 -1.66727e-05 -0.0252713" mass="0.100006" fullinertia="8.3758999999999995e-05 8.1040300000000004e-05 2.39783e-05 7.5552500000000001e-08 -1.1634200000000001e-06 1.5466300000000001e-07"/>
          <geom name="scene//unnamed_geom_5" class="scene/visual" type="mesh" material="scene/sts3215_03a_v1_material" pos="-0.030399200000000001 0.00042224100000000001 -0.041700000000000001" quat="0.5 0.5 0.5 -0.5" mesh="scene/sts3215_03a_v1"/>
          <geom name="scene//unnamed_geom_6" class="scene/collision" type="mesh" material="scene/sts3215_03a_v1_material" pos="-0.030399200000000001 0.00042224100000000001 -0.041700000000000001" quat="0.5 0.5 0.5 -0.5" mesh="scene/sts3215_03a_v1"/>
          <geom name="scene//unnamed_geom_7" class="scene/visual" type="mesh" material="scene/motor_holder_so101_base_v1_material" pos="-0.067599199999999998 -0.00017775899999999999 0.0158499" quat="0.5 0.5 -0.5 0.5" mesh="scene/motor_holder_so101_base_v1"/>
          <geom name="scene//unnamed_geom_8" class="scene/collision" type="mesh" material="scene/motor_holder_so101_base_v1_material" pos="-0.067599199999999998 -0.00017775899999999999 0.0158499" quat="0.5 0.5 -0.5 0.5" mesh="scene/motor_holder_so101_base_v1"/>
          <geom name="scene//unnamed_geom_9" class="scene/visual" type="mesh" material="scene/rotation_pitch_so101_v1_material" pos="0.012200799999999999 2.22413e-05 0.046399999999999997" quat="0.70710700000000004 -0.70710700000000004 -0 8.3162999999999997e-34" mesh="scene/rotation_pitch_so101_v1"/>
          <geom name="scene//unnamed_geom_10" class="scene/collision" type="mesh" material="scene/rotation_pitch_so101_v1_material" pos="0.012200799999999999 2.22413e-05 0.046399999999999997" quat="0.70710700000000004 -0.70710700000000004 -0 8.3162999999999997e-34" mesh="scene/rotation_pitch_so101_v1"/>
          <body name="scene/upper_arm" pos="-0.030399200000000001 -0.0182778 -0.054199999999999998" quat="0.5 -0.5 -0.5 -0.5">
            <joint name="scene/shoulder_lift" class="scene/sts3215" type="hinge" axis="0 0 1" range="-1.7453292519943224 1.7453292519943366"/>
            <inertial pos="-0.089847099999999999 -0.0083822399999999991 0.018408899999999999" mass="0.10299999999999999" fullinertia="4.0800200000000003e-05 0.00014731799999999999 0.00014248700000000001 -1.9781900000000001e-05 -4.0301599999999997e-08 8.9732600000000005e-09"/>
            <geom name="scene//unnamed_geom_11" class="scene/visual" type="mesh" material="scene/sts3215_03a_v1_material" pos="-0.11257 -0.0155 0.018700000000000001" quat="4.5630799999999998e-16 -0.70710700000000004 0.70710700000000004 -1.37383e-16" mesh="scene/sts3215_03a_v1"/>
            <geom name="scene//unnamed_geom_12" class="scene/collision" type="mesh" material="scene/sts3215_03a_v1_material" pos="-0.11257 -0.0155 0.018700000000000001" quat="4.5630799999999998e-16 -0.70710700000000004 0.70710700000000004 -1.37383e-16" mesh="scene/sts3215_03a_v1"/>
            <geom name="scene//unnamed_geom_13" class="scene/visual" type="mesh" material="scene/upper_arm_so101_v1_material" pos="-0.065085000000000004 0.012 0.018200000000000001" quat="0 1 0 0" mesh="scene/upper_arm_so101_v1"/>
            <geom name="scene//unnamed_geom_14" class="scene/collision" type="mesh" material="scene/upper_arm_so101_v1_material" pos="-0.065085000000000004 0.012 0.018200000000000001" quat="0 1 0 0" mesh="scene/upper_arm_so101_v1"/>
            <body name="scene/lower_arm" pos="-0.11257 -0.028000000000000001 1.7376299999999999e-16" quat="0.70710700000000004 -5.9861300000000001e-17 -2.5805100000000001e-17 0.70710700000000004">
              <joint name="scene/elbow_flex" class="scene/sts3215" type="hinge" axis="0 0 1" range="-1.6899999999999999 1.6899999999999999"/>
              <inertial pos="-0.098070099999999993 0.00324376 0.0182831" mass="0.104" fullinertia="2.8743800000000001e-05 0.000159844 0.00014529000000000001 7.4115199999999998e-06 1.26409e-06 -4.90188e-08"/>
              <geom name="scene//unnamed_geom_15" class="scene/visual" type="mesh" material="scene/under_arm_so101_v1_material" pos="-0.064849900000000002 -0.032000000000000001 0.018200000000000001" quat="0 1 0 0" mesh="scene/under_arm_so101_v1"/>
              <geom name="scene//unnamed_geom_16" class="scene/collision" type="mesh" material="scene/under_arm_so101_v1_material" pos="-0.064849900000000002 -0.032000000000000001 0.018200000000000001" quat="0 1 0 0" mesh="scene/under_arm_so101_v1"/>
              <geom name="scene//unnamed_geom_17" class="scene/visual" type="mesh" material="scene/motor_holder_so101_wrist_v1_material" pos="-0.064849900000000002 -0.032000000000000001 0.017999999999999999" quat="3.9268700000000002e-16 -1 -1.9186000000000001e-15 -6.38378e-16" mesh="scene/motor_holder_so101_wrist_v1"/>
              <geom name="scene//unnamed_geom_18" class="scene/collision" type="mesh" material="scene/motor_holder_so101_wrist_v1_material" pos="-0.064849900000000002 -0.032000000000000001 0.017999999999999999" quat="3.9268700000000002e-16 -1 -1.9186000000000001e-15 -6.38378e-16" mesh="scene/motor_holder_so101_wrist_v1"/>
              <geom name="scene//unnamed_geom_19" class="scene/visual" type="mesh" material="scene/sts3215_03a_v1_material" pos="-0.12239999999999999 0.0051999999999999998 0.018700000000000001" quat="7.2164500000000001e-16 1.56949e-15 1 -3.33067e-16" mesh="scene/sts3215_03a_v1"/>
              <geom name="scene//unnamed_geom_20" class="scene/collision" type="mesh" material="scene/sts3215_03a_v1_material" pos="-0.12239999999999999 0.0051999999999999998 0.018700000000000001" quat="7.2164500000000001e-16 1.56949e-15 1 -3.33067e-16" mesh="scene/sts3215_03a_v1"/>
              <body name="scene/wrist" pos="-0.13489999999999999 0.0051999999999999998 3.6235500000000001e-17" quat="0.70710700000000004 9.5872199999999996e-16 -7.5131300000000003e-16 -0.70710700000000004">
                <joint name="scene/wrist_flex" class="scene/sts3215" type="hinge" axis="0 0 1" range="-1.6580628494556928 1.6580627293335335"/>
                <inertial pos="-0.000103312 -0.038614299999999997 0.028115600000000001" mass="0.079000000000000001" fullinertia="3.6826299999999997e-05 2.5391000000000001e-05 2.0999999999999999e-05 1.7893e-08 -5.28128e-08 3.6412e-06"/>
                <geom name="scene//unnamed_geom_21" class="scene/visual" type="mesh" material="scene/sts3215_03a_no_horn_v1_material" pos="8.3266699999999998e-17 -0.0424 0.030599999999999999" quat="0.5 0.5 0.5 -0.5" mesh="scene/sts3215_03a_no_horn_v1"/>
                <geom name="scene//unnamed_geom_22" class="scene/collision" type="mesh" material="scene/sts3215_03a_no_horn_v1_material" pos="8.3266699999999998e-17 -0.0424 0.030599999999999999" quat="0.5 0.5 0.5 -0.5" mesh="scene/sts3215_03a_no_horn_v1"/>
                <geom name="scene//unnamed_geom_23" class="scene/visual" type="mesh" material="scene/wrist_roll_pitch_so101_v2_material" pos="0 -0.028000000000000001 0.018100000000000002" quat="0.5 -0.5 -0.5 -0.5" mesh="scene/wrist_roll_pitch_so101_v2"/>
                <geom name="scene//unnamed_geom_24" class="scene/collision" type="mesh" material="scene/wrist_roll_pitch_so101_v2_material" pos="0 -0.028000000000000001 0.018100000000000002" quat="0.5 -0.5 -0.5 -0.5" mesh="scene/wrist_roll_pitch_so101_v2"/>
                <body name="scene/gripper" pos="5.5511199999999995e-17 -0.061100000000000002 0.018100000000000002" quat="0.017209100000000001 -0.017209100000000001 0.706897 0.706897">
                  <joint name="scene/wrist_roll" class="scene/sts3215" type="hinge" axis="0 0 1" range="-2.7438472969992493 2.841206309382605"/>
                  <inertial pos="0.00021362700000000001 0.000245138 -0.025187000000000001" mass="0.086999999999999994" fullinertia="2.75087e-05 4.3365699999999997e-05 3.4505899999999998e-05 -3.35241e-07 -5.7351999999999997e-06 -5.17847e-08"/>
                  <geom name="scene//unnamed_geom_25" class="scene/visual" type="mesh" material="scene/sts3215_03a_v1_material" pos="0.0077000000000000002 0.0001 -0.023400000000000001" quat="0.70710700000000004 -0.70710700000000004 1.66015e-15 6.4509399999999999e-15" mesh="scene/sts3215_03a_v1"/>
                  <geom name="scene//unnamed_geom_26" class="scene/collision" type="mesh" material="scene/sts3215_03a_v1_material" pos="0.0077000000000000002 0.0001 -0.023400000000000001" quat="0.70710700000000004 -0.70710700000000004 1.66015e-15 6.4509399999999999e-15" mesh="scene/sts3215_03a_v1"/>
                  <geom name="scene//unnamed_geom_27" class="scene/visual" type="mesh" material="scene/wrist_roll_follower_so101_v1_material" pos="8.3266699999999998e-17 -0.00021821399999999999 0.00094970600000000003" quat="0 1 0 0" mesh="scene/wrist_roll_follower_so101_v1"/>
                  <geom name="scene//unnamed_geom_28" class="scene/collision" type="mesh" material="scene/wrist_roll_follower_so101_v1_material" pos="8.3266699999999998e-17 -0.00021821399999999999 0.00094970600000000003" quat="0 1 0 0" mesh="scene/wrist_roll_follower_so101_v1"/>
                  <site name="scene/gripperframe" group="3" pos="-0.0079000000000000008 -0.00021812099999999999 -0.098127400000000004" quat="0.70710700000000004 -0 0.70710700000000004 -2.3778799999999999e-17"/>
                  <body name="scene/moving_jaw_so101_v1" pos="0.020199999999999999 0.018800000000000001 -0.023400000000000001" quat="0.70710700000000004 0.70710700000000004 -1.8536199999999999e-08 1.8536199999999999e-08">
                    <joint name="scene/gripper" class="scene/sts3215" type="hinge" axis="0 0 1" range="-0.17453297762778586 1.7453291995659765"/>
                    <inertial pos="-0.0015749500000000001 -0.0300244 0.019275500000000001" mass="0.012" fullinertia="6.6142699999999999e-06 1.8903200000000001e-06 5.2873799999999998e-06 -3.1980700000000003e-07 -5.90717e-09 -1.09945e-07"/>
                    <geom name="scene//unnamed_geom_29" class="scene/visual" type="mesh" material="scene/moving_jaw_so101_v1_material" pos="-5.5511199999999995e-17 -5.5511199999999995e-17 0.0189" quat="1 -0 3.0052400000000002e-16 -2.0083399999999999e-17" mesh="scene/moving_jaw_so101_v1"/>
                    <geom name="scene//unnamed_geom_30" class="scene/collision" type="mesh" material="scene/moving_jaw_so101_v1_material" pos="-5.5511199999999995e-17 -5.5511199999999995e-17 0.0189" quat="1 -0 3.0052400000000002e-16 -2.0083399999999999e-17" mesh="scene/moving_jaw_so101_v1"/>
                  </body>
                </body>
              </body>
            </body>
          </body>
        </body>
      </body>
    </body>
    <body name="obj_0" pos="-0.28719541231206724 0.2935055390548309 0.20000000000000001">
      <geom name="//unnamed_geom_1" class="/" type="sphere" size="0.050000000000000003" rgba="1 0 0 1"/>
    </body>
    <body name="obj_1" pos="-0.39896911715061922 -0.066041050932771572 0.20000000000000001">
      <geom name="//unnamed_geom_2" class="/" type="sphere" size="0.050000000000000003" rgba="1 0 0 1"/>
    </body>
    <body name="obj_2" pos="-0.15099395193107978 0.48037718407109253 0.20000000000000001">
      <geom name="//unnamed_geom_3" class="/" type="box" size="0.050000000000000003 0.050000000000000003 0.050000000000000003" rgba="0 0 1 1"/>
    </body>
    <body name="obj_3" pos="0.0031755242730272526 0.1859912946158796 0.20000000000000001">
      <geom name="//unnamed_geom_4" class="/" type="box" size="0.050000000000000003 0.050000000000000003 0.050000000000000003" rgba="0 0 1 1"/>
    </body>
    <body name="obj_4" pos="-0.34811248476310486 -0.28038544758236794 0.20000000000000001">
      <geom name="//unnamed_geom_5" class="/" type="box" size="0.050000000000000003 0.050000000000000003 0.050000000000000003" rgba="0 0 1 1"/>
    </body>
  </worldbody>
  <actuator>
    <position name="scene/shoulder_pan" class="scene/sts3215" ctrlrange="-1.9198599999999999 1.9198599999999999" forcerange="-3.3500000000000001 3.3500000000000001" joint="scene/shoulder_pan"/>
    <position name="scene/shoulder_lift" class="scene/sts3215" ctrlrange="-1.74533 1.74533" forcerange="-3.3500000000000001 3.3500000000000001" joint="scene/shoulder_lift"/>
    <position name="scene/elbow_flex" class="scene/sts3215" ctrlrange="-1.6899999999999999 1.6899999999999999" forcerange="-3.3500000000000001 3.3500000000000001" joint="scene/elbow_flex"/>
    <position name="scene/wrist_flex" class="scene/sts3215" ctrlrange="-1.6580600000000001 1.6580600000000001" forcerange="-3.3500000000000001 3.3500000000000001" joint="scene/wrist_flex"/>
    <position name="scene/wrist_roll" class="scene/sts3215" ctrlrange="-2.7438500000000001 2.8412099999999998" forcerange="-3.3500000000000001 3.3500000000000001" joint="scene/wrist_roll"/>
    <position name="scene/gripper" class="scene/sts3215" ctrlrange="-0.17452999999999999 1.74533" forcerange="-3.3500000000000001 3.3500000000000001" joint="scene/gripper"/>
  </actuator>
</mujoco>
