<mujoco model="unnamed_model">
  <compiler angle="radian"/>
  <option timestep="0.002" integrator="implicitfast">
    <flag warmstart="enable"/>
  </option>
  <default>
    <default class="/"/>
    <default class="unnamed_model/"/>
    <default class="scene/">
      <default class="scene/so101_new_calib">
        <joint armature="0.0050000000000000001" damping="1" frictionloss="0.10000000000000001"/>
        <general biastype="affine" gainprm="50" biasprm="0 -50"/>
        <default class="scene/visual">
          <geom type="mesh" contype="0" conaffinity="0" group="2"/>
        </default>
        <default class="scene/collision">
          <geom group="3"/>
        </default>
      </default>
      <default class="scene/sts3215">
        <joint armature="0.028000000000000001" damping="0.59999999999999998" frictionloss="0.051999999999999998"/>
        <geom contype="0" conaffinity="0"/>
        <general biastype="affine" gainprm="17.800000000000001" biasprm="0 -17.800000000000001"/>
      </default>
      <default class="scene/backlash">
        <joint limited="true" range="-0.0087266500000000007 0.0087266500000000007" armature="0.01" damping="0.01"/>
      </default>
    </default>
  </default>
  <asset>
    <texture name="//unnamed_texture_0" type="2d" builtin="checker" rgb1="0.20000000000000001 0.29999999999999999 0.40000000000000002" rgb2="0.29999999999999999 0.40000000000000002 0.5" width="300" height="300"/>
    <material name="grid" class="/" texture="//unnamed_texture_0" texrepeat="5 5" reflectance="0.20000000000000001"/>
    <material name="scene/darkgrey" class="scene/" rgba="0.10000000000000001 0.10000000000000001 0.10000000000000001 1"/>
    <material name="scene/grey" class="scene/" rgba="0.5 0.5 0.5 1"/>
    <material name="scene/blue" class="scene/" rgba="0 0 0.80000000000000004 1"/>
    <material name="scene/base_motor_holder_so101_v1_material" class="scene/" rgba="1 0.81999999999999995 0.12 1"/>
    <material name="scene/base_so101_v2_material" class="scene/" rgba="1 0.81999999999999995 0.12 1"/>
    <material name="scene/sts3215_03a_v1_material" class="scene/" rgba="0.10000000000000001 0.10000000000000001 0.10000000000000001 1"/>
    <material name="scene/waveshare_mounting_plate_so101_v2_material" class="scene/" rgba="1 0.81999999999999995 0.12 1"/>
    <material name="scene/motor_holder_so101_base_v1_material" class="scene/" rgba="1 0.81999999999999995 0.12 1"/>
    <material name="scene/rotation_pitch_so101_v1_material" class="scene/" rgba="1 0.81999999999999995 0.12 1"/>
    <material name="scene/upper_arm_so101_v1_material" class="scene/" rgba="1 0.81999999999999995 0.12 1"/>
    <material name="scene/under_arm_so101_v1_material" class="scene/" rgba="1 0.81999999999999995 0.12 1"/>
    <material name="scene/motor_holder_so101_wrist_v1_material" class="scene/" rgba="1 0.81999999999999995 0.12 1"/>
    <material name="scene/sts3215_03a_no_horn_v1_material" class="scene/" rgba="0.10000000000000001 0.10000000000000001 0.10000000000000001 1"/>
    <material name="scene/wrist_roll_pitch_so101_v2_material" class="scene/" rgba="1 0.81999999999999995 0.12 1"/>
    <material name="scene/wrist_roll_follower_so101_v1_material" class="scene/" rgba="1 0.81999999999999995 0.12 1"/>
    <material name="scene/moving_jaw_so101_v1_material" class="scene/" rgba="1 0.81999999999999995 0.12 1"/>
    <mesh name="scene/waveshare_mounting_plate_so101_v2" content_type="model/stl" class="scene/" file="waveshare_mounting_plate_so101_v2-bdc4594c1957f44d73e6a5364f7b03bd093c6890.stl"/>
    <mesh name="scene/sts3215_03a_v1" content_type="model/stl" class="scene/" file="sts3215_03a_v1-48096645b134fc6e7596205abc199b6bd4d42d2e.stl"/>
    <mesh name="scene/motor_holder_so101_base_v1" content_type="model/stl" class="scene/" file="motor_holder_so101_base_v1-ba6f82816114ac2a03d9c52c36542b5b83e1cacb.stl"/>
    <mesh name="scene/wrist_roll_follower_so101_v1" content_type="model/stl" class="scene/" file="wrist_roll_follower_so101_v1-1390ac1f92d1a9a8eca02928a45b1490c8f378b2.stl"/>
    <mesh name="scene/moving_jaw_so101_v1" content_type="model/stl" class="scene/" file="moving_jaw_so101_v1-b6a41be828f9c5577dd0199b7e4c8d35c927ded2.stl"/>
    <mesh name="scene/base_motor_holder_so101_v1" content_type="model/stl" class="scene/" file="base_motor_holder_so101_v1-bc95b2736c48967dd6bd8e8a2f52242bc89646fa.stl"/>
    <mesh name="scene/upper_arm_so101_v1" content_type="model/stl" class="scene/" file="upper_arm_so101_v1-b939afe42bcca9c3e448797ee275d5166c6b3dcb.stl"/>
    <mesh name="scene/wrist_roll_pitch_so101_v2" content_type="model/stl" class="scene/" file="wrist_roll_pitch_so101_v2-cbb1b45ea25e6399a1d3321c70d7fcaf37441e6d.stl"/>
    <mesh name="scene/under_arm_so101_v1" content_type="model/stl" class="scene/" file="under_arm_so101_v1-f9b17147dd5786ea6c729dd8439bc8e43512d671.stl"/>
    <mesh name="scene/rotation_pitch_so101_v1" content_type="model/stl" class="scene/" file="rotation_pitch_so101_v1-ec1d01337ede85fa8589cca645336a7a18af2870.stl"/>
    <mesh name="scene/motor_holder_so101_wrist_v1" content_type="model/stl" class="scene/" file="motor_holder_so101_wrist_v1-4b80e458bdc13da15d80c2f1aac2568a487039c8.stl"/>
    <mesh name="scene/sts3215_03a_no_horn_v1" content_type="model/stl" class="scene/" file="sts3215_03a_no_horn_v1-e9103d14a7c0f059d5c33db4828d79632d0a28a3.stl"/>
    <mesh name="scene/base_so101_v2" content_type="model/stl" class="scene/" file="base_so101_v2-6749fa4eebf909cd3026a16775220eaefca3c50f.stl"/>
    <mesh name="scene/fl_wheel_mesh" content_type="model/stl" class="scene/" file="fl_wheel_link-097cfd4973e9082aef3485e74893868ce931387f.STL" scale="0.59999999999999998 0.59999999999999998 0.59999999999999998"/>
    <mesh name="scene/fr_wheel_mesh" content_type="model/stl" class="scene/" file="fr_wheel_link-6cf28ba2389a8f6885b950de037feac72102324e.STL" scale="0.59999999999999998 0.59999999999999998 0.59999999999999998"/>
    <mesh name="scene/rl_wheel_mesh" content_type="model/stl" class="scene/" file="rl_wheel_link-f16e2dec35055b6a7c0a27ece4558bcfda15e5ac.STL" scale="0.59999999999999998 0.59999999999999998 0.59999999999999998"/>
    <mesh name="scene/rr_wheel_mesh" content_type="model/stl" class="scene/" file="rr_wheel_link-1f37784bf1080e665eb9d1711ff24204b335f97d.STL" scale="0.59999999999999998 0.59999999999999998 0.59999999999999998"/>
  </asset>
  <worldbody>
    <geom name="//unnamed_geom_0" class="/" type="plane" size="2 2 0.10000000000000001" material="grid"/>
    <light name="//unnamed_light_0" class="/" pos="-2 -1 3" dir="2 1 -2"/>
    <light name="//unnamed_light_1" class="/" pos="2 -1 3" dir="-2 1 -2"/>
    <body pos="0.5 0 0" quat="1 0 0 0" name="unnamed_model/">
      <geom name="unnamed_model//unnamed_geom_0" class="unnamed_model/" type="box" size="0.02 0.02 0.02" rgba="1 0 0 1" pos="0.5 0 0"/>
    </body>
    <body pos="0 0 0" quat="1 0 0 0" name="scene/">
      <freejoint name="scene/"/>
      <body name="scene/base_link" pos="0 0 0.050000000000000003" quat="0.00079632699999999999 0 0 1">
        <inertial pos="0 0 0" mass="4" diaginertia="0.0065669999999999999 0.013367 0.019599999999999999"/>
        <geom name="scene/base_geom_visual" class="scene/visual" type="box" size="0.20000000000000001 0.14000000000000001 0.01" material="scene/grey"/>
        <geom name="scene/base_geom_collision" class="scene/collision" type="box" size="0.20000000000000001 0.14000000000000001 0.01" material="scene/grey"/>
        <body name="scene/fl_wheel_link" pos="-0.17999999999999999 -0.16 -0.029999999999999999" quat="0.70710700000000004 -0.70710700000000004 0 0">
          <inertial pos="0 0 0" mass="0.5" diaginertia="0.000176 0.000176 0.00028899999999999998"/>
          <joint name="scene/fl_wheel_joint" class="scene/" pos="0 0 0" axis="0 0 -1"/>
          <geom name="scene/fl_wheel_visual" class="scene/visual" material="scene/darkgrey" pos="0 0 0.014999999999999999" quat="0.70710700000000004 0 0.70710700000000004 0" mesh="scene/fl_wheel_mesh"/>
          <geom name="scene/fl_wheel_collision" class="scene/collision" type="cylinder" size="0.034000000000000002 0.014" material="scene/darkgrey" friction="1.2 0.050000000000000003 0.050000000000000003"/>
        </body>
        <body name="scene/fr_wheel_link" pos="-0.17999999999999999 0.16 -0.029999999999999999" quat="0.70710700000000004 0.70710700000000004 0 0">
          <inertial pos="0 0 0" mass="0.5" diaginertia="0.000176 0.000176 0.00028899999999999998"/>
          <joint name="scene/fr_wheel_joint" class="scene/" pos="0 0 0" axis="0 0 1"/>
          <geom name="scene/fr_wheel_visual" class="scene/visual" material="scene/darkgrey" pos="0 0 0.014999999999999999" quat="0.70710700000000004 0 0.70710700000000004 0" mesh="scene/fr_wheel_mesh"/>
          <geom name="scene/fr_wheel_collision" class="scene/collision" type="cylinder" size="0.034000000000000002 0.014" material="scene/darkgrey" friction="1.2 0.050000000000000003 0.050000000000000003"/>
        </body>
        <body name="scene/rl_wheel_link" pos="0.17999999999999999 -0.16 -0.029999999999999999" quat="0.70710700000000004 -0.70710700000000004 0 0">
          <inertial pos="0 0 0" mass="0.5" diaginertia="0.000176 0.000176 0.00028899999999999998"/>
          <joint name="scene/rl_wheel_joint" class="scene/" pos="0 0 0" axis="0 0 -1"/>
          <geom name="scene/rl_wheel_visual" class="scene/visual" material="scene/darkgrey" pos="0 0 0.014999999999999999" quat="0.70710700000000004 0 0.70710700000000004 0" mesh="scene/rl_wheel_mesh"/>
          <geom name="scene/rl_wheel_collision" class="scene/collision" type="cylinder" size="0.034000000000000002 0.014" material="scene/darkgrey" friction="1.2 0.050000000000000003 0.050000000000000003"/>
        </body>
        <body name="scene/rr_wheel_link" pos="0.17999999999999999 0.16 -0.029999999999999999" quat="0.70710700000000004 0.70710700000000004 0 0">
          <inertial pos="0 0 0" mass="0.5" diaginertia="0.000176 0.000176 0.00028899999999999998"/>
          <joint name="scene/rr_wheel_joint" class="scene/" pos="0 0 0" axis="0 0 1"/>
          <geom name="scene/rr_wheel_visual" class="scene/visual" material="scene/darkgrey" pos="0 0 0.014999999999999999" quat="0.70710700000000004 0 0.70710700000000004 0" mesh="scene/rr_wheel_mesh"/>
          <geom name="scene/rr_wheel_collision" class="scene/collision" type="cylinder" size="0.034000000000000002 0.014" material="scene/darkgrey" friction="1.2 0.050000000000000003 0.050000000000000003"/>
        </body>
      </body>
      <body name="scene/base" childclass="scene/so101_new_calib" pos="0.10000000000000001 0 0.059999999999999998">
        <inertial pos="0.0137179 -5.1971100000000001e-05 0.033484300000000002" quat="0.42051899999999998 0.55876199999999998 0.57198000000000004 0.42870399999999997" mass="0.14699999999999999" diaginertia="0.00013612699999999999 0.00013180700000000001 0.000113233"/>
        <geom name="scene//unnamed_geom_10" class="scene/visual" material="scene/base_motor_holder_so101_v1_material" pos="-0.00636471 -9.94414e-05 -0.0023999999999999998" quat="0.5 0.5 0.5 0.5" mesh="scene/base_motor_holder_so101_v1"/>
        <geom name="scene//unnamed_geom_11" class="scene/visual" material="scene/base_so101_v2_material" pos="-0.00636471 -8.9765700000000002e-09 -0.0023999999999999998" quat="0.5 0.5 0.5 0.5" mesh="scene/base_so101_v2"/>
        <geom name="scene//unnamed_geom_12" class="scene/visual" material="scene/sts3215_03a_v1_material" pos="0.026335299999999999 -8.9765700000000002e-09 0.043700000000000003" quat="1 0 0 0" mesh="scene/sts3215_03a_v1"/>
        <geom name="scene//unnamed_geom_13" class="scene/visual" material="scene/waveshare_mounting_plate_so101_v2_material" pos="-0.030982699999999998 -0.00019944099999999999 0.047399999999999998" quat="0.5 0.5 0.5 0.5" mesh="scene/waveshare_mounting_plate_so101_v2"/>
        <site name="scene/baseframe" group="3" pos="0 0 0" quat="1 0 0 0"/>
        <body name="scene/shoulder" pos="0.038835300000000003 -8.9765700000000002e-09 0.062399999999999997" quat="0 0 -1 0">
          <inertial pos="-0.0307604 -1.66727e-05 -0.0252713" quat="0.999865 0.00149563 0.0097084000000000007 0.0132043" mass="0.100006" diaginertia="8.3783599999999995e-05 8.1038799999999994e-05 2.3955200000000001e-05"/>
          <joint name="scene/shoulder_pan" class="scene/sts3215" pos="0 0 0" axis="0 0 1" range="-1.9198599999999999 1.9198599999999999"/>
          <geom name="scene//unnamed_geom_14" class="scene/visual" material="scene/sts3215_03a_v1_material" pos="-0.030399200000000001 0.00042224100000000001 -0.041700000000000001" quat="0.5 0.5 0.5 -0.5" mesh="scene/sts3215_03a_v1"/>
          <geom name="scene//unnamed_geom_15" class="scene/collision" type="mesh" material="scene/sts3215_03a_v1_material" pos="-0.030399200000000001 0.00042224100000000001 -0.041700000000000001" quat="0.5 0.5 0.5 -0.5" mesh="scene/sts3215_03a_v1"/>
          <geom name="scene//unnamed_geom_16" class="scene/visual" material="scene/motor_holder_so101_base_v1_material" pos="-0.067599199999999998 -0.00017775899999999999 0.0158499" quat="0.5 0.5 -0.5 0.5" mesh="scene/motor_holder_so101_base_v1"/>
          <geom name="scene//unnamed_geom_17" class="scene/collision" type="mesh" material="scene/motor_holder_so101_base_v1_material" pos="-0.067599199999999998 -0.00017775899999999999 0.0158499" quat="0.5 0.5 -0.5 0.5" mesh="scene/motor_holder_so101_base_v1"/>
          <geom name="scene//unnamed_geom_18" class="scene/visual" material="scene/rotation_pitch_so101_v1_material" pos="0.012200799999999999 2.22413e-05 0.046399999999999997" quat="0.70710700000000004 -0.70710700000000004 0 0" mesh="scene/rotation_pitch_so101_v1"/>
          <geom name="scene//unnamed_geom_19" class="scene/collision" type="mesh" material="scene/rotation_pitch_so101_v1_material" pos="0.012200799999999999 2.22413e-05 0.046399999999999997" quat="0.70710700000000004 -0.70710700000000004 0 0" mesh="scene/rotation_pitch_so101_v1"/>
          <body name="scene/upper_arm" pos="-0.030399200000000001 -0.0182778 -0.054199999999999998" quat="0.5 -0.5 -0.5 -0.5">
            <inertial pos="-0.089847099999999999 -0.0083822399999999991 0.018408899999999999" quat="0.45319500000000001 0.45406299999999999 0.54189100000000001 0.54295099999999996" mass="0.10299999999999999" diaginertia="0.00015087299999999999 0.00014248700000000001 3.72451e-05"/>
            <joint name="scene/shoulder_lift" class="scene/sts3215" pos="0 0 0" axis="0 0 1" range="-1.74533 1.74533"/>
            <geom name="scene//unnamed_geom_20" class="scene/visual" material="scene/sts3215_03a_v1_material" pos="-0.11257 -0.0155 0.018700000000000001" quat="0 -0.70710700000000004 0.70710700000000004 0" mesh="scene/sts3215_03a_v1"/>
            <geom name="scene//unnamed_geom_21" class="scene/collision" type="mesh" material="scene/sts3215_03a_v1_material" pos="-0.11257 -0.0155 0.018700000000000001" quat="0 -0.70710700000000004 0.70710700000000004 0" mesh="scene/sts3215_03a_v1"/>
            <geom name="scene//unnamed_geom_22" class="scene/visual" material="scene/upper_arm_so101_v1_material" pos="-0.065085000000000004 0.012 0.018200000000000001" quat="0 1 0 0" mesh="scene/upper_arm_so101_v1"/>
            <geom name="scene//unnamed_geom_23" class="scene/collision" type="mesh" material="scene/upper_arm_so101_v1_material" pos="-0.065085000000000004 0.012 0.018200000000000001" quat="0 1 0 0" mesh="scene/upper_arm_so101_v1"/>
            <body name="scene/lower_arm" pos="-0.11257 -0.028000000000000001 0" quat="0.70710700000000004 0 0 0.70710700000000004">
              <inertial pos="-0.098070099999999993 0.00324376 0.0182831" quat="0.51072899999999999 0.51700599999999997 0.48796600000000001 0.48347699999999999" mass="0.104" diaginertia="0.00016026199999999999 0.00014530399999999999 2.83125e-05"/>
              <joint name="scene/elbow_flex" class="scene/sts3215" pos="0 0 0" axis="0 0 1" range="-1.6899999999999999 1.6899999999999999"/>
              <geom name="scene//unnamed_geom_24" class="scene/visual" material="scene/under_arm_so101_v1_material" pos="-0.064849900000000002 -0.032000000000000001 0.018200000000000001" quat="0 1 0 0" mesh="scene/under_arm_so101_v1"/>
              <geom name="scene//unnamed_geom_25" class="scene/collision" type="mesh" material="scene/under_arm_so101_v1_material" pos="-0.064849900000000002 -0.032000000000000001 0.018200000000000001" quat="0 1 0 0" mesh="scene/under_arm_so101_v1"/>
              <geom name="scene//unnamed_geom_26" class="scene/visual" material="scene/motor_holder_so101_wrist_v1_material" pos="-0.064849900000000002 -0.032000000000000001 0.017999999999999999" quat="0 -1 0 0" mesh="scene/motor_holder_so101_wrist_v1"/>
              <geom name="scene//unnamed_geom_27" class="scene/collision" type="mesh" material="scene/motor_holder_so101_wrist_v1_material" pos="-0.064849900000000002 -0.032000000000000001 0.017999999999999999" quat="0 -1 0 0" mesh="scene/motor_holder_so101_wrist_v1"/>
              <geom name="scene//unnamed_geom_28" class="scene/visual" material="scene/sts3215_03a_v1_material" pos="-0.12239999999999999 0.0051999999999999998 0.018700000000000001" quat="0 0 1 0" mesh="scene/sts3215_03a_v1"/>
              <geom name="scene//unnamed_geom_29" class="scene/collision" type="mesh" material="scene/sts3215_03a_v1_material" pos="-0.12239999999999999 0.0051999999999999998 0.018700000000000001" quat="0 0 1 0" mesh="scene/sts3215_03a_v1"/>
              <body name="scene/wrist" pos="-0.13489999999999999 0.0051999999999999998 0" quat="0.70710700000000004 0 0 -0.70710700000000004">
                <inertial pos="-0.000103312 -0.038614299999999997 0.028115600000000001" quat="0.96714299999999997 0.25422600000000001 0.0016222599999999999 -0.00014630700000000001" mass="0.079000000000000001" diaginertia="3.6826499999999997e-05 2.7447400000000001e-05 1.8943399999999999e-05"/>
                <joint name="scene/wrist_flex" class="scene/sts3215" pos="0 0 0" axis="0 0 1" range="-1.6580600000000001 1.6580600000000001"/>
                <geom name="scene//unnamed_geom_30" class="scene/visual" material="scene/sts3215_03a_no_horn_v1_material" pos="0 -0.0424 0.030599999999999999" quat="0.5 0.5 0.5 -0.5" mesh="scene/sts3215_03a_no_horn_v1"/>
                <geom name="scene//unnamed_geom_31" class="scene/collision" type="mesh" material="scene/sts3215_03a_no_horn_v1_material" pos="0 -0.0424 0.030599999999999999" quat="0.5 0.5 0.5 -0.5" mesh="scene/sts3215_03a_no_horn_v1"/>
                <geom name="scene//unnamed_geom_32" class="scene/visual" material="scene/wrist_roll_pitch_so101_v2_material" pos="0 -0.028000000000000001 0.018100000000000002" quat="0.5 -0.5 -0.5 -0.5" mesh="scene/wrist_roll_pitch_so101_v2"/>
                <geom name="scene//unnamed_geom_33" class="scene/collision" type="mesh" material="scene/wrist_roll_pitch_so101_v2_material" pos="0 -0.028000000000000001 0.018100000000000002" quat="0.5 -0.5 -0.5 -0.5" mesh="scene/wrist_roll_pitch_so101_v2"/>
                <body name="scene/gripper" pos="0 -0.061100000000000002 0.018100000000000002" quat="0.017209100000000001 -0.017209100000000001 0.706897 0.706897">
                  <inertial pos="0.00021362700000000001 0.000245138 -0.025187000000000001" quat="0.60071699999999995 0.355993 0.35863 0.61951000000000001" mass="0.086999999999999994" diaginertia="4.3373500000000001e-05 3.7722899999999998e-05 2.42839e-05"/>
                  <joint name="scene/wrist_roll" class="scene/sts3215" pos="0 0 0" axis="0 0 1" range="-2.7438500000000001 2.8412099999999998"/>
                  <geom name="scene//unnamed_geom_34" class="scene/visual" material="scene/sts3215_03a_v1_material" pos="0.0077000000000000002 0.0001 -0.023400000000000001" quat="0.70710700000000004 -0.70710700000000004 0 0" mesh="scene/sts3215_03a_v1"/>
                  <geom name="scene//unnamed_geom_35" class="scene/collision" type="mesh" material="scene/sts3215_03a_v1_material" pos="0.0077000000000000002 0.0001 -0.023400000000000001" quat="0.70710700000000004 -0.70710700000000004 0 0" mesh="scene/sts3215_03a_v1"/>
                  <geom name="scene//unnamed_geom_36" class="scene/visual" material="scene/wrist_roll_follower_so101_v1_material" pos="0 -0.00021821399999999999 0.00094970600000000003" quat="0 1 0 0" mesh="scene/wrist_roll_follower_so101_v1"/>
                  <geom name="scene//unnamed_geom_37" class="scene/collision" type="mesh" material="scene/wrist_roll_follower_so101_v1_material" pos="0 -0.00021821399999999999 0.00094970600000000003" quat="0 1 0 0" mesh="scene/wrist_roll_follower_so101_v1"/>
                  <site name="scene/gripperframe" group="3" pos="-0.0079000000000000008 -0.00021812099999999999 -0.098127400000000004" quat="0.70710700000000004 0 0.70710700000000004 0"/>
                  <body name="scene/moving_jaw_so101_v1" pos="0.020199999999999999 0.018800000000000001 -0.023400000000000001" quat="0.70710700000000004 0.70710700000000004 -1.8536199999999999e-08 1.8536199999999999e-08">
                    <inertial pos="-0.0015749500000000001 -0.0300244 0.019275500000000001" quat="0.69526500000000002 0.71796499999999996 -0.024561800000000002 -0.023009700000000001" mass="0.012" diaginertia="6.6358199999999998e-06 5.2909200000000002e-06 1.8652299999999999e-06"/>
                    <joint name="scene/gripper" class="scene/sts3215" pos="0 0 0" axis="0 0 1" range="-0.17453299999999999 1.74533"/>
                    <geom name="scene//unnamed_geom_38" class="scene/visual" material="scene/moving_jaw_so101_v1_material" pos="0 0 0.0189" quat="1 0 0 0" mesh="scene/moving_jaw_so101_v1"/>
                    <geom name="scene//unnamed_geom_39" class="scene/collision" type="mesh" material="scene/moving_jaw_so101_v1_material" pos="0 0 0.0189" quat="1 0 0 0" mesh="scene/moving_jaw_so101_v1"/>
                  </body>
                </body>
              </body>
            </body>
          </body>
        </body>
      </body>
    </body>
  </worldbody>
  <actuator>
    <general name="scene/fl_wheel_motor" class="scene/" ctrlrange="-10.470000000000001 10.470000000000001" joint="scene/fl_wheel_joint" biastype="affine" gainprm="0.10000000000000001" biasprm="0 0 -0.10000000000000001"/>
    <general name="scene/fr_wheel_motor" class="scene/" ctrlrange="-10.470000000000001 10.470000000000001" joint="scene/fr_wheel_joint" biastype="affine" gainprm="0.10000000000000001" biasprm="0 0 -0.10000000000000001"/>
    <general name="scene/rl_wheel_motor" class="scene/" ctrlrange="-10.470000000000001 10.470000000000001" joint="scene/rl_wheel_joint" biastype="affine" gainprm="0.10000000000000001" biasprm="0 0 -0.10000000000000001"/>
    <general name="scene/rr_wheel_motor" class="scene/" ctrlrange="-10.470000000000001 10.470000000000001" joint="scene/rr_wheel_joint" biastype="affine" gainprm="0.10000000000000001" biasprm="0 0 -0.10000000000000001"/>
    <general name="scene/shoulder_pan" class="scene/sts3215" ctrlrange="-1.9198599999999999 1.9198599999999999" forcerange="-3.3500000000000001 3.3500000000000001" joint="scene/shoulder_pan"/>
    <general name="scene/shoulder_lift" class="scene/sts3215" ctrlrange="-1.74533 1.74533" forcerange="-3.3500000000000001 3.3500000000000001" joint="scene/shoulder_lift"/>
    <general name="scene/elbow_flex" class="scene/sts3215" ctrlrange="-1.6899999999999999 1.6899999999999999" forcerange="-3.3500000000000001 3.3500000000000001" joint="scene/elbow_flex"/>
    <general name="scene/wrist_flex" class="scene/sts3215" ctrlrange="-1.6580600000000001 1.6580600000000001" forcerange="-3.3500000000000001 3.3500000000000001" joint="scene/wrist_flex"/>
    <general name="scene/wrist_roll" class="scene/sts3215" ctrlrange="-2.7438500000000001 2.8412099999999998" forcerange="-3.3500000000000001 3.3500000000000001" joint="scene/wrist_roll"/>
    <general name="scene/gripper" class="scene/sts3215" ctrlrange="-0.17452999999999999 1.74533" forcerange="-3.3500000000000001 3.3500000000000001" joint="scene/gripper"/>
  </actuator>
</mujoco>
