<mujoco model="scene">
  <compiler angle="radian" meshdir="assets/" texturedir="assets/"/>

  <option timestep="0.004" integrator="implicitfast"/>

  <default>
    <default class="so101_new_calib">
      <joint armature="0.005" damping="1" frictionloss="0.1"/>
      <general biastype="affine" gainprm="50" biasprm="0 -50"/>
      <default class="visual">
        <geom type="mesh" contype="0" conaffinity="0" group="2"/>
      </default>
      <default class="collision">
        <geom group="3"/>
      </default>
    </default>
    <default class="sts3215">
      <joint armature="0.028" damping="0.6" frictionloss="0.052"/>
      <geom contype="0" conaffinity="0"/>
      <general biastype="affine" gainprm="17.8" biasprm="0 -17.8"/>
    </default>
    <default class="backlash">
      <joint limited="true" range="-0.00872665 0.00872665" armature="0.01" damping="0.01"/>
    </default>
  </default>

  <asset>
   
    <material name="darkgrey" rgba="0.1 0.1 0.1 1"/>
    <material name="grey" rgba="0.5 0.5 0.5 1"/>
    <material name="blue" rgba="0 0 0.8 1"/>
    <material name="base_motor_holder_so101_v1_material" rgba="1 0.82 0.12 1"/>
    <material name="base_so101_v2_material" rgba="1 0.82 0.12 1"/>
    <material name="sts3215_03a_v1_material" rgba="0.1 0.1 0.1 1"/>
    <material name="waveshare_mounting_plate_so101_v2_material" rgba="1 0.82 0.12 1"/>
    <material name="motor_holder_so101_base_v1_material" rgba="1 0.82 0.12 1"/>
    <material name="rotation_pitch_so101_v1_material" rgba="1 0.82 0.12 1"/>
    <material name="upper_arm_so101_v1_material" rgba="1 0.82 0.12 1"/>
    <material name="under_arm_so101_v1_material" rgba="1 0.82 0.12 1"/>
    <material name="motor_holder_so101_wrist_v1_material" rgba="1 0.82 0.12 1"/>
    <material name="sts3215_03a_no_horn_v1_material" rgba="0.1 0.1 0.1 1"/>
    <material name="wrist_roll_pitch_so101_v2_material" rgba="1 0.82 0.12 1"/>
    <material name="wrist_roll_follower_so101_v1_material" rgba="1 0.82 0.12 1"/>
    <material name="moving_jaw_so101_v1_material" rgba="1 0.82 0.12 1"/>
    <mesh name="waveshare_mounting_plate_so101_v2" content_type="model/stl" file="/home/sunny24/rl_mm/asset/SO101/assets/waveshare_mounting_plate_so101_v2.stl"/>
    <mesh name="sts3215_03a_v1" content_type="model/stl" file="/home/sunny24/rl_mm/asset/SO101/assets/sts3215_03a_v1.stl"/>
    <mesh name="motor_holder_so101_base_v1" content_type="model/stl" file="/home/sunny24/rl_mm/asset/SO101/assets/motor_holder_so101_base_v1.stl"/>
    <mesh name="wrist_roll_follower_so101_v1" content_type="model/stl" file="/home/sunny24/rl_mm/asset/SO101/assets/wrist_roll_follower_so101_v1.stl"/>
    <mesh name="moving_jaw_so101_v1" content_type="model/stl" file="/home/sunny24/rl_mm/asset/SO101/assets/moving_jaw_so101_v1.stl"/>
    <mesh name="base_motor_holder_so101_v1" content_type="model/stl" file="/home/sunny24/rl_mm/asset/SO101/assets/base_motor_holder_so101_v1.stl"/>
    <mesh name="upper_arm_so101_v1" content_type="model/stl" file="/home/sunny24/rl_mm/asset/SO101/assets/upper_arm_so101_v1.stl"/>
    <mesh name="wrist_roll_pitch_so101_v2" content_type="model/stl" file="/home/sunny24/rl_mm/asset/SO101/assets/wrist_roll_pitch_so101_v2.stl"/>
    <mesh name="under_arm_so101_v1" content_type="model/stl" file="/home/sunny24/rl_mm/asset/SO101/assets/under_arm_so101_v1.stl"/>
    <mesh name="rotation_pitch_so101_v1" content_type="model/stl" file="/home/sunny24/rl_mm/asset/SO101/assets/rotation_pitch_so101_v1.stl"/>
    <mesh name="motor_holder_so101_wrist_v1" content_type="model/stl" file="/home/sunny24/rl_mm/asset/SO101/assets/motor_holder_so101_wrist_v1.stl"/>
    <mesh name="sts3215_03a_no_horn_v1" content_type="model/stl" file="/home/sunny24/rl_mm/asset/SO101/assets/sts3215_03a_no_horn_v1.stl"/>
    <mesh name="base_so101_v2" content_type="model/stl" file="/home/sunny24/rl_mm/asset/SO101/assets/base_so101_v2.stl"/>
    <mesh name="fl_wheel_mesh" content_type="model/stl" file="/home/sunny24/rl_mm/asset/mecanum/meshes/fl_wheel_link.STL" scale="0.6 0.6 0.6"/>
    <mesh name="fr_wheel_mesh" content_type="model/stl" file="/home/sunny24/rl_mm/asset/mecanum/meshes/fr_wheel_link.STL" scale="0.6 0.6 0.6"/>
    <mesh name="rl_wheel_mesh" content_type="model/stl" file="/home/sunny24/rl_mm/asset/mecanum/meshes/rl_wheel_link.STL" scale="0.6 0.6 0.6"/>
    <mesh name="rr_wheel_mesh" content_type="model/stl" file="/home/sunny24/rl_mm/asset/mecanum/meshes/rr_wheel_link.STL" scale="0.6 0.6 0.6"/>
  </asset>

  <worldbody>

    <!-- <body name="scene/"> -->
      <!-- <joint type="free"/> -->
      <!-- <freejoint/> -->
      <body name="base_link" pos="0 0 0.05" quat="0.000796327 0 0 1">
        <inertial pos="0 0 0" mass="4" diaginertia="0.006567 0.013367 0.0196"/>
        <geom name="base_geom_visual" class="visual" size="0.2 0.14 0.01" type="box" material="grey"/>
        <geom name="base_geom_collision" class="collision" size="0.2 0.14 0.01" type="box" material="grey"/>
        <body name="fl_wheel_link" pos="-0.18 -0.16 -0.03" quat="0.707107 -0.707107 0 0">
          <inertial pos="0 0 0" mass="0.5" diaginertia="0.000176 0.000176 0.000289"/>
          <joint name="fl_wheel_joint" pos="0 0 0" axis="0 0 -1"/>
          <geom name="fl_wheel_visual" class="visual" pos="0 0 0.015" quat="0.707107 0 0.707107 0" material="darkgrey" mesh="fl_wheel_mesh"/>
          <geom name="fl_wheel_collision" class="collision" size="0.034 0.014" type="cylinder" friction="1.2 0.05 0.05" material="darkgrey"/>
        </body>
        <body name="fr_wheel_link" pos="-0.18 0.16 -0.03" quat="0.707107 0.707107 0 0">
          <inertial pos="0 0 0" mass="0.5" diaginertia="0.000176 0.000176 0.000289"/>
          <joint name="fr_wheel_joint" pos="0 0 0" axis="0 0 1"/>
          <geom name="fr_wheel_visual" class="visual" pos="0 0 0.015" quat="0.707107 0 0.707107 0" material="darkgrey" mesh="fr_wheel_mesh"/>
          <geom name="fr_wheel_collision" class="collision" size="0.034 0.014" type="cylinder" friction="1.2 0.05 0.05" material="darkgrey"/>
        </body>
        <body name="rl_wheel_link" pos="0.18 -0.16 -0.03" quat="0.707107 -0.707107 0 0">
          <inertial pos="0 0 0" mass="0.5" diaginertia="0.000176 0.000176 0.000289"/>
          <joint name="rl_wheel_joint" pos="0 0 0" axis="0 0 -1"/>
          <geom name="rl_wheel_visual" class="visual" pos="0 0 0.015" quat="0.707107 0 0.707107 0" material="darkgrey" mesh="rl_wheel_mesh"/>
          <geom name="rl_wheel_collision" class="collision" size="0.034 0.014" type="cylinder" friction="1.2 0.05 0.05" material="darkgrey"/>
        </body>
        <body name="rr_wheel_link" pos="0.18 0.16 -0.03" quat="0.707107 0.707107 0 0">
          <inertial pos="0 0 0" mass="0.5" diaginertia="0.000176 0.000176 0.000289"/>
          <joint name="rr_wheel_joint" pos="0 0 0" axis="0 0 1"/>
          <geom name="rr_wheel_visual" class="visual" pos="0 0 0.015" quat="0.707107 0 0.707107 0" material="darkgrey" mesh="rr_wheel_mesh"/>
          <geom name="rr_wheel_collision" class="collision" size="0.034 0.014" type="cylinder" friction="1.2 0.05 0.05" material="darkgrey"/>
        </body>
      </body>
      <body name="base" childclass="so101_new_calib" pos="0.1 0 0.06">
        <inertial pos="0.0137179 -5.19711e-05 0.0334843" quat="0.420519 0.558762 0.57198 0.428704" mass="0.147" diaginertia="0.000136127 0.000131807 0.000113233"/>
        <geom class="visual" pos="-0.00636471 -9.94414e-05 -0.0024" quat="0.5 0.5 0.5 0.5" material="base_motor_holder_so101_v1_material" mesh="base_motor_holder_so101_v1"/>
        <geom class="visual" pos="-0.00636471 -8.97657e-09 -0.0024" quat="0.5 0.5 0.5 0.5" material="base_so101_v2_material" mesh="base_so101_v2"/>
        <geom class="visual" pos="0.0263353 -8.97657e-09 0.0437" quat="1 0 0 0" material="sts3215_03a_v1_material" mesh="sts3215_03a_v1"/>
        <geom class="visual" pos="-0.0309827 -0.000199441 0.0474" quat="0.5 0.5 0.5 0.5" material="waveshare_mounting_plate_so101_v2_material" mesh="waveshare_mounting_plate_so101_v2"/>
        <site name="baseframe" pos="0 0 0" quat="1 0 0 0" group="3"/>
        <body name="shoulder" pos="0.0388353 -8.97657e-09 0.0624" quat="0 0 -1 0">
          <inertial pos="-0.0307604 -1.66727e-05 -0.0252713" quat="0.999865 0.00149563 0.0097084 0.0132043" mass="0.100006" diaginertia="8.37836e-05 8.10388e-05 2.39552e-05"/>
          <joint name="shoulder_pan" class="sts3215" pos="0 0 0" axis="0 0 1" range="-1.91986 1.91986"/>
          <geom class="visual" pos="-0.0303992 0.000422241 -0.0417" quat="0.5 0.5 0.5 -0.5" material="sts3215_03a_v1_material" mesh="sts3215_03a_v1"/>
          <geom class="collision" pos="-0.0303992 0.000422241 -0.0417" quat="0.5 0.5 0.5 -0.5" type="mesh" material="sts3215_03a_v1_material" mesh="sts3215_03a_v1"/>
          <geom class="visual" pos="-0.0675992 -0.000177759 0.0158499" quat="0.5 0.5 -0.5 0.5" material="motor_holder_so101_base_v1_material" mesh="motor_holder_so101_base_v1"/>
          <geom class="collision" pos="-0.0675992 -0.000177759 0.0158499" quat="0.5 0.5 -0.5 0.5" type="mesh" material="motor_holder_so101_base_v1_material" mesh="motor_holder_so101_base_v1"/>
          <geom class="visual" pos="0.0122008 2.22413e-05 0.0464" quat="0.707107 -0.707107 0 0" material="rotation_pitch_so101_v1_material" mesh="rotation_pitch_so101_v1"/>
          <geom class="collision" pos="0.0122008 2.22413e-05 0.0464" quat="0.707107 -0.707107 0 0" type="mesh" material="rotation_pitch_so101_v1_material" mesh="rotation_pitch_so101_v1"/>
          <body name="upper_arm" pos="-0.0303992 -0.0182778 -0.0542" quat="0.5 -0.5 -0.5 -0.5">
            <inertial pos="-0.0898471 -0.00838224 0.0184089" quat="0.453195 0.454063 0.541891 0.542951" mass="0.103" diaginertia="0.000150873 0.000142487 3.72451e-05"/>
            <joint name="shoulder_lift" class="sts3215" pos="0 0 0" axis="0 0 1" range="-1.74533 1.74533"/>
            <geom class="visual" pos="-0.11257 -0.0155 0.0187" quat="0 -0.707107 0.707107 0" material="sts3215_03a_v1_material" mesh="sts3215_03a_v1"/>
            <geom class="collision" pos="-0.11257 -0.0155 0.0187" quat="0 -0.707107 0.707107 0" type="mesh" material="sts3215_03a_v1_material" mesh="sts3215_03a_v1"/>
            <geom class="visual" pos="-0.065085 0.012 0.0182" quat="0 1 0 0" material="upper_arm_so101_v1_material" mesh="upper_arm_so101_v1"/>
            <geom class="collision" pos="-0.065085 0.012 0.0182" quat="0 1 0 0" type="mesh" material="upper_arm_so101_v1_material" mesh="upper_arm_so101_v1"/>
            <body name="lower_arm" pos="-0.11257 -0.028 0" quat="0.707107 0 0 0.707107">
              <inertial pos="-0.0980701 0.00324376 0.0182831" quat="0.510729 0.517006 0.487966 0.483477" mass="0.104" diaginertia="0.000160262 0.000145304 2.83125e-05"/>
              <joint name="elbow_flex" class="sts3215" pos="0 0 0" axis="0 0 1" range="-1.69 1.69"/>
              <geom class="visual" pos="-0.0648499 -0.032 0.0182" quat="0 1 0 0" material="under_arm_so101_v1_material" mesh="under_arm_so101_v1"/>
              <geom class="collision" pos="-0.0648499 -0.032 0.0182" quat="0 1 0 0" type="mesh" material="under_arm_so101_v1_material" mesh="under_arm_so101_v1"/>
              <geom class="visual" pos="-0.0648499 -0.032 0.018" quat="0 -1 0 0" material="motor_holder_so101_wrist_v1_material" mesh="motor_holder_so101_wrist_v1"/>
              <geom class="collision" pos="-0.0648499 -0.032 0.018" quat="0 -1 0 0" type="mesh" material="motor_holder_so101_wrist_v1_material" mesh="motor_holder_so101_wrist_v1"/>
              <geom class="visual" pos="-0.1224 0.0052 0.0187" quat="0 0 1 0" material="sts3215_03a_v1_material" mesh="sts3215_03a_v1"/>
              <geom class="collision" pos="-0.1224 0.0052 0.0187" quat="0 0 1 0" type="mesh" material="sts3215_03a_v1_material" mesh="sts3215_03a_v1"/>
              <body name="wrist" pos="-0.1349 0.0052 0" quat="0.707107 0 0 -0.707107">
                <inertial pos="-0.000103312 -0.0386143 0.0281156" quat="0.967143 0.254226 0.00162226 -0.000146307" mass="0.079" diaginertia="3.68265e-05 2.74474e-05 1.89434e-05"/>
                <joint name="wrist_flex" class="sts3215" pos="0 0 0" axis="0 0 1" range="-1.65806 1.65806"/>
                <geom class="visual" pos="0 -0.0424 0.0306" quat="0.5 0.5 0.5 -0.5" material="sts3215_03a_no_horn_v1_material" mesh="sts3215_03a_no_horn_v1"/>
                <geom class="collision" pos="0 -0.0424 0.0306" quat="0.5 0.5 0.5 -0.5" type="mesh" material="sts3215_03a_no_horn_v1_material" mesh="sts3215_03a_no_horn_v1"/>
                <geom class="visual" pos="0 -0.028 0.0181" quat="0.5 -0.5 -0.5 -0.5" material="wrist_roll_pitch_so101_v2_material" mesh="wrist_roll_pitch_so101_v2"/>
                <geom class="collision" pos="0 -0.028 0.0181" quat="0.5 -0.5 -0.5 -0.5" type="mesh" material="wrist_roll_pitch_so101_v2_material" mesh="wrist_roll_pitch_so101_v2"/>
                <body name="gripper" pos="0 -0.0611 0.0181" quat="0.0172091 -0.0172091 0.706897 0.706897">
                  <inertial pos="0.000213627 0.000245138 -0.025187" quat="0.600717 0.355993 0.35863 0.61951" mass="0.087" diaginertia="4.33735e-05 3.77229e-05 2.42839e-05"/>
                  <joint name="wrist_roll" class="sts3215" pos="0 0 0" axis="0 0 1" range="-2.74385 2.84121"/>
                  <geom class="visual" pos="0.0077 0.0001 -0.0234" quat="0.707107 -0.707107 0 0" material="sts3215_03a_v1_material" mesh="sts3215_03a_v1"/>
                  <geom class="collision" pos="0.0077 0.0001 -0.0234" quat="0.707107 -0.707107 0 0" type="mesh" material="sts3215_03a_v1_material" mesh="sts3215_03a_v1"/>
                  <geom class="visual" pos="0 -0.000218214 0.000949706" quat="0 1 0 0" material="wrist_roll_follower_so101_v1_material" mesh="wrist_roll_follower_so101_v1"/>
                  <geom class="collision" pos="0 -0.000218214 0.000949706" quat="0 1 0 0" type="mesh" material="wrist_roll_follower_so101_v1_material" mesh="wrist_roll_follower_so101_v1"/>
                  <site name="gripperframe" pos="-0.0079 -0.000218121 -0.0981274" quat="0.707107 0 0.707107 0" group="3"/>
                  <body name="moving_jaw_so101_v1" pos="0.0202 0.0188 -0.0234" quat="0.707107 0.707107 -1.85362e-08 1.85362e-08">
                    <inertial pos="-0.00157495 -0.0300244 0.0192755" quat="0.695265 0.717965 -0.0245618 -0.0230097" mass="0.012" diaginertia="6.63582e-06 5.29092e-06 1.86523e-06"/>
                    <joint name="gripper" class="sts3215" pos="0 0 0" axis="0 0 1" range="-0.174533 1.74533"/>
                    <geom class="visual" pos="0 0 0.0189" quat="1 0 0 0" material="moving_jaw_so101_v1_material" mesh="moving_jaw_so101_v1"/>
                    <geom class="collision" pos="0 0 0.0189" quat="1 0 0 0" type="mesh" material="moving_jaw_so101_v1_material" mesh="moving_jaw_so101_v1"/>
                  </body>
                </body>
              </body>
            </body>
          </body>
        </body>
      </body>
    <!-- </body> -->
  </worldbody>

  <actuator>
    <general name="fl_wheel_joint" joint="fl_wheel_joint" ctrlrange="-20.47 20.47" biastype="affine" gainprm="0.1" biasprm="0 0 -0.1"/>
    <general name="fr_wheel_joint" joint="fr_wheel_joint" ctrlrange="-20.47 20.47" biastype="affine" gainprm="0.1" biasprm="0 0 -0.1"/>
    <general name="rl_wheel_joint" joint="rl_wheel_joint" ctrlrange="-20.47 20.47" biastype="affine" gainprm="0.1" biasprm="0 0 -0.1"/>
    <general name="rr_wheel_joint" joint="rr_wheel_joint" ctrlrange="-20.47 20.47" biastype="affine" gainprm="0.1" biasprm="0 0 -0.1"/>
    <general name="shoulder_pan" class="sts3215" joint="shoulder_pan" ctrlrange="-1.91986 1.91986" forcerange="-3.35 3.35"/>
    <general name="shoulder_lift" class="sts3215" joint="shoulder_lift" ctrlrange="-1.74533 1.74533" forcerange="-3.35 3.35"/>
    <general name="elbow_flex" class="sts3215" joint="elbow_flex" ctrlrange="-1.69 1.69" forcerange="-3.35 3.35"/>
    <general name="wrist_flex" class="sts3215" joint="wrist_flex" ctrlrange="-1.65806 1.65806" forcerange="-3.35 3.35"/>
    <general name="wrist_roll" class="sts3215" joint="wrist_roll" ctrlrange="-2.74385 2.84121" forcerange="-3.35 3.35"/>
    <general name="gripper" class="sts3215" joint="gripper" ctrlrange="-0.17453 1.74533" forcerange="-3.35 3.35"/>
  </actuator>
</mujoco>
